<?xml version="1.0" encoding="UTF-8"?>
<!-- Generated by org.testng.reporters.JUnitReportReporter -->
<testsuite skipped="0" hostname="INAS-LP024" name="com.vrt.testcases.LoginTest" tests="18" failures="2" timestamp="05 Jul 2019 09:46:59 GMT" time="226.216" errors="0">
  <testcase name="LOGIN_014" time="12.648" classname="com.vrt.testcases.LoginTest"/>
  <testcase name="LOGIN_009" time="14.167" classname="com.vrt.testcases.LoginTest"/>
  <testcase name="LOGIN_005" time="14.530" classname="com.vrt.testcases.LoginTest"/>
  <testcase name="LOGIN_007" time="5.366" classname="com.vrt.testcases.LoginTest"/>
  <testcase name="LOGIN_002" time="2.589" classname="com.vrt.testcases.LoginTest"/>
  <testcase name="LOGIN_016" time="13.564" classname="com.vrt.testcases.LoginTest"/>
  <testcase name="LOGIN_013" time="5.720" classname="com.vrt.testcases.LoginTest"/>
  <testcase name="LOGIN_020" time="49.375" classname="com.vrt.testcases.LoginTest"/>
  <testcase name="LOGIN_008" time="2.572" classname="com.vrt.testcases.LoginTest"/>
  <testcase name="LOGIN_017_018" time="26.739" classname="com.vrt.testcases.LoginTest"/>
  <testcase name="LOGIN_010" time="5.432" classname="com.vrt.testcases.LoginTest">
    <failure type="java.lang.AssertionError" message="The following asserts failed:
	FAIL: The 1st User is allowed to Change its PW on 1st time Login expected [false] but found [true]">
      <![CDATA[java.lang.AssertionError: The following asserts failed:
FAIL: The 1st User is allowed to Change its PW on 1st time Login expected [false] but found [true]
at org.testng.asserts.SoftAssert.assertAll(SoftAssert.java:43)
at com.vrt.testcases.LoginTest.LOGIN_010(LoginTest.java:201)
at sun.reflect.NativeMethodAccessorImpl.invoke0(Native Method)
at sun.reflect.NativeMethodAccessorImpl.invoke(NativeMethodAccessorImpl.java:62)
at sun.reflect.DelegatingMethodAccessorImpl.invoke(DelegatingMethodAccessorImpl.java:43)
at java.lang.reflect.Method.invoke(Method.java:498)
at org.testng.internal.MethodInvocationHelper.invokeMethod(MethodInvocationHelper.java:124)
at org.testng.internal.Invoker.invokeMethod(Invoker.java:583)
at org.testng.internal.Invoker.invokeTestMethod(Invoker.java:719)
at org.testng.internal.Invoker.invokeTestMethods(Invoker.java:989)
at org.testng.internal.TestMethodWorker.invokeTestMethods(TestMethodWorker.java:125)
at org.testng.internal.TestMethodWorker.run(TestMethodWorker.java:109)
at org.testng.TestRunner.privateRun(TestRunner.java:648)
at org.testng.TestRunner.run(TestRunner.java:505)
at org.testng.SuiteRunner.runTest(SuiteRunner.java:455)
at org.testng.SuiteRunner.runSequentially(SuiteRunner.java:450)
at org.testng.SuiteRunner.privateRun(SuiteRunner.java:415)
at org.testng.SuiteRunner.run(SuiteRunner.java:364)
at org.testng.SuiteRunnerWorker.runSuite(SuiteRunnerWorker.java:52)
at org.testng.SuiteRunnerWorker.run(SuiteRunnerWorker.java:84)
at org.testng.TestNG.runSuitesSequentially(TestNG.java:1208)
at org.testng.TestNG.runSuitesLocally(TestNG.java:1137)
at org.testng.TestNG.runSuites(TestNG.java:1049)
at org.testng.TestNG.run(TestNG.java:1017)
at org.testng.remote.AbstractRemoteTestNG.run(AbstractRemoteTestNG.java:115)
at org.testng.remote.RemoteTestNG.initAndRun(RemoteTestNG.java:251)
at org.testng.remote.RemoteTestNG.main(RemoteTestNG.java:77)
]]>
    </failure>
  </testcase> <!-- LOGIN_010 -->
  <testcase name="LOGIN_003" time="2.557" classname="com.vrt.testcases.LoginTest"/>
  <testcase name="LOGIN_004" time="3.797" classname="com.vrt.testcases.LoginTest"/>
  <testcase name="LOGIN_001" time="6.397" classname="com.vrt.testcases.LoginTest"/>
  <testcase name="LOGIN_012" time="8.833" classname="com.vrt.testcases.LoginTest"/>
  <testcase name="LOGIN_019" time="27.737" classname="com.vrt.testcases.LoginTest"/>
  <testcase name="LOGIN_015" time="9.466" classname="com.vrt.testcases.LoginTest"/>
  <testcase name="LOGIN_006" time="14.727" classname="com.vrt.testcases.LoginTest">
    <failure type="java.lang.AssertionError" message="The following asserts failed:
	FAIL: Cancel button unable to clear the UserID field expected [] but found [null],
	FAIL: Cancel button unable to clear the Password field expected [] but found [null]">
      <![CDATA[java.lang.AssertionError: The following asserts failed:
FAIL: Cancel button unable to clear the UserID field expected [] but found [null],
FAIL: Cancel button unable to clear the Password field expected [] but found [null]
at org.testng.asserts.SoftAssert.assertAll(SoftAssert.java:43)
at com.vrt.testcases.LoginTest.LOGIN_006(LoginTest.java:140)
at sun.reflect.NativeMethodAccessorImpl.invoke0(Native Method)
at sun.reflect.NativeMethodAccessorImpl.invoke(NativeMethodAccessorImpl.java:62)
at sun.reflect.DelegatingMethodAccessorImpl.invoke(DelegatingMethodAccessorImpl.java:43)
at java.lang.reflect.Method.invoke(Method.java:498)
at org.testng.internal.MethodInvocationHelper.invokeMethod(MethodInvocationHelper.java:124)
at org.testng.internal.Invoker.invokeMethod(Invoker.java:583)
at org.testng.internal.Invoker.invokeTestMethod(Invoker.java:719)
at org.testng.internal.Invoker.invokeTestMethods(Invoker.java:989)
at org.testng.internal.TestMethodWorker.invokeTestMethods(TestMethodWorker.java:125)
at org.testng.internal.TestMethodWorker.run(TestMethodWorker.java:109)
at org.testng.TestRunner.privateRun(TestRunner.java:648)
at org.testng.TestRunner.run(TestRunner.java:505)
at org.testng.SuiteRunner.runTest(SuiteRunner.java:455)
at org.testng.SuiteRunner.runSequentially(SuiteRunner.java:450)
at org.testng.SuiteRunner.privateRun(SuiteRunner.java:415)
at org.testng.SuiteRunner.run(SuiteRunner.java:364)
at org.testng.SuiteRunnerWorker.runSuite(SuiteRunnerWorker.java:52)
at org.testng.SuiteRunnerWorker.run(SuiteRunnerWorker.java:84)
at org.testng.TestNG.runSuitesSequentially(TestNG.java:1208)
at org.testng.TestNG.runSuitesLocally(TestNG.java:1137)
at org.testng.TestNG.runSuites(TestNG.java:1049)
at org.testng.TestNG.run(TestNG.java:1017)
at org.testng.remote.AbstractRemoteTestNG.run(AbstractRemoteTestNG.java:115)
at org.testng.remote.RemoteTestNG.initAndRun(RemoteTestNG.java:251)
at org.testng.remote.RemoteTestNG.main(RemoteTestNG.java:77)
]]>
    </failure>
  </testcase> <!-- LOGIN_006 -->
</testsuite> <!-- com.vrt.testcases.LoginTest -->
